2023-05-09 20:25:11.639 | ERROR    | __main__:main:15 - This event loop is already running
Traceback (most recent call last):

  File "C:\Users\zhvit\AppData\Local\Programs\Python\Python310\lib\site-packages\aiogram\utils\executor.py", line 320, in start_polling
    loop.run_until_complete(self._startup_polling())
    │    │                  │    └ <function Executor._startup_polling at 0x0000023D0AA40D30>
    │    │                  └ <aiogram.utils.executor.Executor object at 0x0000023D0AAF78B0>
    │    └ <function BaseEventLoop.run_until_complete at 0x0000023D08D1D120>
    └ <ProactorEventLoop running=True closed=False debug=False>

  File "C:\Users\zhvit\AppData\Local\Programs\Python\Python310\lib\asyncio\base_events.py", line 625, in run_until_complete
    self._check_running()
    │    └ <function BaseEventLoop._check_running at 0x0000023D08D1D000>
    └ <ProactorEventLoop running=True closed=False debug=False>

  File "C:\Users\zhvit\AppData\Local\Programs\Python\Python310\lib\asyncio\base_events.py", line 584, in _check_running
    raise RuntimeError('This event loop is already running')

RuntimeError: This event loop is already running


During handling of the above exception, another exception occurred:


Traceback (most recent call last):

  File "C:\Users\zhvit\YandexDisk\ChatWatchdogBot\main.py", line 20, in <module>
    asyncio.run(main())
    │       │   └ <function main at 0x0000023D06CBFC70>
    │       └ <function run at 0x0000023D08D176D0>
    └ <module 'asyncio' from 'C:\\Users\\zhvit\\AppData\\Local\\Programs\\Python\\Python310\\lib\\asyncio\\__init__.py'>

  File "C:\Users\zhvit\AppData\Local\Programs\Python\Python310\lib\asyncio\runners.py", line 44, in run
    return loop.run_until_complete(main)
           │    │                  └ <coroutine object main at 0x0000023D0AAF12A0>
           │    └ <function BaseEventLoop.run_until_complete at 0x0000023D08D1D120>
           └ <ProactorEventLoop running=True closed=False debug=False>

  File "C:\Users\zhvit\AppData\Local\Programs\Python\Python310\lib\asyncio\base_events.py", line 636, in run_until_complete
    self.run_forever()
    │    └ <function ProactorEventLoop.run_forever at 0x0000023D08DD1B40>
    └ <ProactorEventLoop running=True closed=False debug=False>

  File "C:\Users\zhvit\AppData\Local\Programs\Python\Python310\lib\asyncio\windows_events.py", line 321, in run_forever
    super().run_forever()

  File "C:\Users\zhvit\AppData\Local\Programs\Python\Python310\lib\asyncio\base_events.py", line 603, in run_forever
    self._run_once()
    │    └ <function BaseEventLoop._run_once at 0x0000023D08D1EB90>
    └ <ProactorEventLoop running=True closed=False debug=False>

  File "C:\Users\zhvit\AppData\Local\Programs\Python\Python310\lib\asyncio\base_events.py", line 1909, in _run_once
    handle._run()
    │      └ <function Handle._run at 0x0000023D08C7E0E0>
    └ <Handle <TaskStepMethWrapper object at 0x0000023D0AAF7880>()>

  File "C:\Users\zhvit\AppData\Local\Programs\Python\Python310\lib\asyncio\events.py", line 80, in _run
    self._context.run(self._callback, *self._args)
    │    │            │    │           │    └ <member '_args' of 'Handle' objects>
    │    │            │    │           └ <Handle <TaskStepMethWrapper object at 0x0000023D0AAF7880>()>
    │    │            │    └ <member '_callback' of 'Handle' objects>
    │    │            └ <Handle <TaskStepMethWrapper object at 0x0000023D0AAF7880>()>
    │    └ <member '_context' of 'Handle' objects>
    └ <Handle <TaskStepMethWrapper object at 0x0000023D0AAF7880>()>

> File "C:\Users\zhvit\YandexDisk\ChatWatchdogBot\main.py", line 13, in main
    await executor.start_polling(dp, skip_updates=True)
          │        │             └ <aiogram.dispatcher.dispatcher.Dispatcher object at 0x0000023D0AAF62F0>
          │        └ <function start_polling at 0x0000023D0AA40040>
          └ <module 'aiogram.utils.executor' from 'C:\\Users\\zhvit\\AppData\\Local\\Programs\\Python\\Python310\\lib\\site-packages\\aio...

  File "C:\Users\zhvit\AppData\Local\Programs\Python\Python310\lib\site-packages\aiogram\utils\executor.py", line 45, in start_polling
    executor.start_polling(
    │        └ <function Executor.start_polling at 0x0000023D0AA40A60>
    └ <aiogram.utils.executor.Executor object at 0x0000023D0AAF78B0>

  File "C:\Users\zhvit\AppData\Local\Programs\Python\Python310\lib\site-packages\aiogram\utils\executor.py", line 328, in start_polling
    loop.run_until_complete(self._shutdown_polling())
    │    │                  │    └ <function Executor._shutdown_polling at 0x0000023D0AA40DC0>
    │    │                  └ <aiogram.utils.executor.Executor object at 0x0000023D0AAF78B0>
    │    └ <function BaseEventLoop.run_until_complete at 0x0000023D08D1D120>
    └ <ProactorEventLoop running=True closed=False debug=False>

  File "C:\Users\zhvit\AppData\Local\Programs\Python\Python310\lib\asyncio\base_events.py", line 625, in run_until_complete
    self._check_running()
    │    └ <function BaseEventLoop._check_running at 0x0000023D08D1D000>
    └ <ProactorEventLoop running=True closed=False debug=False>

  File "C:\Users\zhvit\AppData\Local\Programs\Python\Python310\lib\asyncio\base_events.py", line 584, in _check_running
    raise RuntimeError('This event loop is already running')

RuntimeError: This event loop is already running
2023-05-09 20:28:24.279 | ERROR    | __main__:main:15 - This event loop is already running
Traceback (most recent call last):

  File "C:\Users\zhvit\AppData\Local\Programs\Python\Python310\lib\site-packages\aiogram\utils\executor.py", line 320, in start_polling
    loop.run_until_complete(self._startup_polling())
    │    │                  │    └ <function Executor._startup_polling at 0x000001CA9A2F0D30>
    │    │                  └ <aiogram.utils.executor.Executor object at 0x000001CA9A3A7790>
    │    └ <function BaseEventLoop.run_until_complete at 0x000001CA9864D120>
    └ <ProactorEventLoop running=True closed=False debug=False>

  File "C:\Users\zhvit\AppData\Local\Programs\Python\Python310\lib\asyncio\base_events.py", line 625, in run_until_complete
    self._check_running()
    │    └ <function BaseEventLoop._check_running at 0x000001CA9864D000>
    └ <ProactorEventLoop running=True closed=False debug=False>

  File "C:\Users\zhvit\AppData\Local\Programs\Python\Python310\lib\asyncio\base_events.py", line 584, in _check_running
    raise RuntimeError('This event loop is already running')

RuntimeError: This event loop is already running


During handling of the above exception, another exception occurred:


Traceback (most recent call last):

  File "C:\Users\zhvit\YandexDisk\ChatWatchdogBot\main.py", line 20, in <module>
    asyncio.run(main())
    │       │   └ <function main at 0x000001CA9659FB50>
    │       └ <function run at 0x000001CA986476D0>
    └ <module 'asyncio' from 'C:\\Users\\zhvit\\AppData\\Local\\Programs\\Python\\Python310\\lib\\asyncio\\__init__.py'>

  File "C:\Users\zhvit\AppData\Local\Programs\Python\Python310\lib\asyncio\runners.py", line 44, in run
    return loop.run_until_complete(main)
           │    │                  └ <coroutine object main at 0x000001CA9A30BAE0>
           │    └ <function BaseEventLoop.run_until_complete at 0x000001CA9864D120>
           └ <ProactorEventLoop running=True closed=False debug=False>

  File "C:\Users\zhvit\AppData\Local\Programs\Python\Python310\lib\asyncio\base_events.py", line 636, in run_until_complete
    self.run_forever()
    │    └ <function ProactorEventLoop.run_forever at 0x000001CA98711B40>
    └ <ProactorEventLoop running=True closed=False debug=False>

  File "C:\Users\zhvit\AppData\Local\Programs\Python\Python310\lib\asyncio\windows_events.py", line 321, in run_forever
    super().run_forever()

  File "C:\Users\zhvit\AppData\Local\Programs\Python\Python310\lib\asyncio\base_events.py", line 603, in run_forever
    self._run_once()
    │    └ <function BaseEventLoop._run_once at 0x000001CA9864EB90>
    └ <ProactorEventLoop running=True closed=False debug=False>

  File "C:\Users\zhvit\AppData\Local\Programs\Python\Python310\lib\asyncio\base_events.py", line 1909, in _run_once
    handle._run()
    │      └ <function Handle._run at 0x000001CA985B20E0>
    └ <Handle <TaskStepMethWrapper object at 0x000001CA9A3A7760>()>

  File "C:\Users\zhvit\AppData\Local\Programs\Python\Python310\lib\asyncio\events.py", line 80, in _run
    self._context.run(self._callback, *self._args)
    │    │            │    │           │    └ <member '_args' of 'Handle' objects>
    │    │            │    │           └ <Handle <TaskStepMethWrapper object at 0x000001CA9A3A7760>()>
    │    │            │    └ <member '_callback' of 'Handle' objects>
    │    │            └ <Handle <TaskStepMethWrapper object at 0x000001CA9A3A7760>()>
    │    └ <member '_context' of 'Handle' objects>
    └ <Handle <TaskStepMethWrapper object at 0x000001CA9A3A7760>()>

> File "C:\Users\zhvit\YandexDisk\ChatWatchdogBot\main.py", line 13, in main
    await executor.start_polling(dp, skip_updates=True)
          │        │             └ <aiogram.dispatcher.dispatcher.Dispatcher object at 0x000001CA9A3A61D0>
          │        └ <function start_polling at 0x000001CA9A2F0040>
          └ <module 'aiogram.utils.executor' from 'C:\\Users\\zhvit\\AppData\\Local\\Programs\\Python\\Python310\\lib\\site-packages\\aio...

  File "C:\Users\zhvit\AppData\Local\Programs\Python\Python310\lib\site-packages\aiogram\utils\executor.py", line 45, in start_polling
    executor.start_polling(
    │        └ <function Executor.start_polling at 0x000001CA9A2F0A60>
    └ <aiogram.utils.executor.Executor object at 0x000001CA9A3A7790>

  File "C:\Users\zhvit\AppData\Local\Programs\Python\Python310\lib\site-packages\aiogram\utils\executor.py", line 328, in start_polling
    loop.run_until_complete(self._shutdown_polling())
    │    │                  │    └ <function Executor._shutdown_polling at 0x000001CA9A2F0DC0>
    │    │                  └ <aiogram.utils.executor.Executor object at 0x000001CA9A3A7790>
    │    └ <function BaseEventLoop.run_until_complete at 0x000001CA9864D120>
    └ <ProactorEventLoop running=True closed=False debug=False>

  File "C:\Users\zhvit\AppData\Local\Programs\Python\Python310\lib\asyncio\base_events.py", line 625, in run_until_complete
    self._check_running()
    │    └ <function BaseEventLoop._check_running at 0x000001CA9864D000>
    └ <ProactorEventLoop running=True closed=False debug=False>

  File "C:\Users\zhvit\AppData\Local\Programs\Python\Python310\lib\asyncio\base_events.py", line 584, in _check_running
    raise RuntimeError('This event loop is already running')

RuntimeError: This event loop is already running
2023-05-09 20:32:54.881 | ERROR    | __main__:main:17 - This event loop is already running
Traceback (most recent call last):

  File "C:\Users\zhvit\AppData\Local\Programs\Python\Python310\lib\site-packages\aiogram\utils\executor.py", line 320, in start_polling
    loop.run_until_complete(self._startup_polling())
    │    │                  │    └ <function Executor._startup_polling at 0x00000207E2DD0D30>
    │    │                  └ <aiogram.utils.executor.Executor object at 0x00000207E3014B20>
    │    └ <function BaseEventLoop.run_until_complete at 0x00000207E110D120>
    └ <ProactorEventLoop running=True closed=False debug=False>

  File "C:\Users\zhvit\AppData\Local\Programs\Python\Python310\lib\asyncio\base_events.py", line 625, in run_until_complete
    self._check_running()
    │    └ <function BaseEventLoop._check_running at 0x00000207E110D000>
    └ <ProactorEventLoop running=True closed=False debug=False>

  File "C:\Users\zhvit\AppData\Local\Programs\Python\Python310\lib\asyncio\base_events.py", line 584, in _check_running
    raise RuntimeError('This event loop is already running')

RuntimeError: This event loop is already running


During handling of the above exception, another exception occurred:


Traceback (most recent call last):

  File "C:\Users\zhvit\YandexDisk\ChatWatchdogBot\main.py", line 22, in <module>
    asyncio.run(main())
    │       │   └ <function main at 0x00000207E3024C10>
    │       └ <function run at 0x00000207E11076D0>
    └ <module 'asyncio' from 'C:\\Users\\zhvit\\AppData\\Local\\Programs\\Python\\Python310\\lib\\asyncio\\__init__.py'>

  File "C:\Users\zhvit\AppData\Local\Programs\Python\Python310\lib\asyncio\runners.py", line 44, in run
    return loop.run_until_complete(main)
           │    │                  └ <coroutine object main at 0x00000207E2E9A260>
           │    └ <function BaseEventLoop.run_until_complete at 0x00000207E110D120>
           └ <ProactorEventLoop running=True closed=False debug=False>

  File "C:\Users\zhvit\AppData\Local\Programs\Python\Python310\lib\asyncio\base_events.py", line 636, in run_until_complete
    self.run_forever()
    │    └ <function ProactorEventLoop.run_forever at 0x00000207E11D1B40>
    └ <ProactorEventLoop running=True closed=False debug=False>

  File "C:\Users\zhvit\AppData\Local\Programs\Python\Python310\lib\asyncio\windows_events.py", line 321, in run_forever
    super().run_forever()

  File "C:\Users\zhvit\AppData\Local\Programs\Python\Python310\lib\asyncio\base_events.py", line 603, in run_forever
    self._run_once()
    │    └ <function BaseEventLoop._run_once at 0x00000207E110EB90>
    └ <ProactorEventLoop running=True closed=False debug=False>

  File "C:\Users\zhvit\AppData\Local\Programs\Python\Python310\lib\asyncio\base_events.py", line 1909, in _run_once
    handle._run()
    │      └ <function Handle._run at 0x00000207E106E0E0>
    └ <Handle <TaskStepMethWrapper object at 0x00000207E3015870>()>

  File "C:\Users\zhvit\AppData\Local\Programs\Python\Python310\lib\asyncio\events.py", line 80, in _run
    self._context.run(self._callback, *self._args)
    │    │            │    │           │    └ <member '_args' of 'Handle' objects>
    │    │            │    │           └ <Handle <TaskStepMethWrapper object at 0x00000207E3015870>()>
    │    │            │    └ <member '_callback' of 'Handle' objects>
    │    │            └ <Handle <TaskStepMethWrapper object at 0x00000207E3015870>()>
    │    └ <member '_context' of 'Handle' objects>
    └ <Handle <TaskStepMethWrapper object at 0x00000207E3015870>()>

> File "C:\Users\zhvit\YandexDisk\ChatWatchdogBot\main.py", line 15, in main
    await executor.start_polling(dp, skip_updates=True)
          │        │             └ <aiogram.dispatcher.dispatcher.Dispatcher object at 0x00000207E2E91510>
          │        └ <function start_polling at 0x00000207E2DD0040>
          └ <module 'aiogram.utils.executor' from 'C:\\Users\\zhvit\\AppData\\Local\\Programs\\Python\\Python310\\lib\\site-packages\\aio...

  File "C:\Users\zhvit\AppData\Local\Programs\Python\Python310\lib\site-packages\aiogram\utils\executor.py", line 45, in start_polling
    executor.start_polling(
    │        └ <function Executor.start_polling at 0x00000207E2DD0A60>
    └ <aiogram.utils.executor.Executor object at 0x00000207E3014B20>

  File "C:\Users\zhvit\AppData\Local\Programs\Python\Python310\lib\site-packages\aiogram\utils\executor.py", line 328, in start_polling
    loop.run_until_complete(self._shutdown_polling())
    │    │                  │    └ <function Executor._shutdown_polling at 0x00000207E2DD0DC0>
    │    │                  └ <aiogram.utils.executor.Executor object at 0x00000207E3014B20>
    │    └ <function BaseEventLoop.run_until_complete at 0x00000207E110D120>
    └ <ProactorEventLoop running=True closed=False debug=False>

  File "C:\Users\zhvit\AppData\Local\Programs\Python\Python310\lib\asyncio\base_events.py", line 625, in run_until_complete
    self._check_running()
    │    └ <function BaseEventLoop._check_running at 0x00000207E110D000>
    └ <ProactorEventLoop running=True closed=False debug=False>

  File "C:\Users\zhvit\AppData\Local\Programs\Python\Python310\lib\asyncio\base_events.py", line 584, in _check_running
    raise RuntimeError('This event loop is already running')

RuntimeError: This event loop is already running
